Workbook

Sheet Dashboard
B2: 📊 Análisis Inteligente de Sueldos — Panel KPI de Nómina
B5: Sueldos más claros | Mejor gente | Negocio más sólido Proyecto de portafolio · Datos ficticios · Octubre 2026 (datos al 20/10)
B6: FILTRAR POR DEPARTAMENTO ▸ | E6: Todos | H6: Elige un departamento en la lista: se actualizan las tarjetas, la tendencia, el histograma y los hallazgos.
B9: TOTAL EMPLEADOS | F9: COSTO TOTAL NÓMINA | J9: SALARIO PROMEDIO | N9: % PAGO A TIEMPO | R9: NUEVAS CONTRATACIONES | V9: TASA DE ROTACIÓN
B10: =Calculos!B6 -> 120 | F10: =Calculos!B7 -> 404470 | J10: =Calculos!B8 -> 3370.5833 | N10: =Calculos!B9 -> 0.99193548 | R10: =Calculos!B10 -> 6 | V10: =Calculos!B11 -> 0.033333333
B12: =IF(ROUND(Calculos!D6*100,1)=0,"● sin cambio vs. mes ant.",IF(Calculos!D6>0,"▲ ","▼ ")&ROUND(ABS(Calculos!D6)*100,1)&"% vs. mes ant.") -> ▲ 1.7% vs. mes ant. | F12: =IF(ROUND(Calculos!D7*100,1)=0,"● sin cambio vs. mes ant.",IF(Calculos!D7>0,"▲ ","▼ ")&ROUND(ABS(Calculos!D7)*100,1)&"% vs. mes ant.") -> ▲ 2.9% vs. mes ant. | J12: =IF(ROUND(Calculos!D8*100,1)=0,"● sin cambio vs. mes ant.",IF(Calculos!D8>0,"▲ ","▼ ")&ROUND(ABS(Calculos!D8)*100,1)&"% vs. mes ant.") -> ▲ 1.1% vs. mes ant. | N12: =IF(ROUND(Calculos!D9*100,1)=0,"● sin cambio vs. mes ant.",IF(Calculos!D9>0,"▲ ","▼ ")&ROUND(ABS(Calculos!D9)*100,1)&" pp vs. mes ant.") -> ▲ 0.9 pp vs. mes ant. | R12: =IF(ROUND(Calculos!D10*100,1)=0,"● sin cambio vs. mes ant.",IF(Calculos!D10>0,"▲ ","▼ ")&ROUND(ABS(Calculos!D10)*100,1)&"% vs. mes ant.") -> ▲ 50% vs. mes ant. | V12: =IF(ROUND(Calculos!D11*100,1)=0,"● sin cambio vs. mes ant.",IF(Calculos!D11>0,"▲ ","▼ ")&ROUND(ABS(Calculos!D11)*100,1)&" pp vs. mes ant.") -> ▲ 1.6 pp vs. mes ant.
B15: Tendencia nómina, salario y dotación por departamento
B37: Distribución de salarios, desempeño y hallazgos
R38: ="Hallazgos clave · vista: "&Calculos!B2 -> Hallazgos clave · vista: Todos
R39: ="• "&INDEX(Calculos!$A$15:$A$19,MATCH(MAX(Calculos!$B$15:$B$19),Calculos!$B$15:$B$19,0))&" tiene el salario promedio más alto ($"&FIXED(MAX(Calculos!$B$15:$B$19),0)&") y "&INDEX(Calculos!$A$15:$A$19,MATCH(MIN(Calculos!$B$15:$B$19),Calculos!$B$15:$B$19,0))&" el más bajo ($"&FIXED(MIN(Calculos!$B$15:$B$19),0)&")." -> • IT tiene el salario promedio más alto ($3,803) y Operaciones el más bajo ($3,028).
R43: ="• Entre mayo y octubre la dotación pasó de "&Nomina_Mensual!D2&" a "&Nomina_Mensual!D7&" empleados y la nómina de $"&FIXED(Nomina_Mensual!E2,0)&" a $"&FIXED(Nomina_Mensual!E7,0)&" ("&IF(Nomina_Mensual!E7>=Nomina_Mensual!E2,"+","-")&ROUND(ABS(IFERROR(Nomina_Mensual!E7/Nomina_Mensual!E2-1,0))*100,1)&"%)." -> • Entre mayo y octubre la dotación pasó de 107 a 120 empleados y la nómina de $354,390 a $404,470 (+14.1%).
R47: ="• La rotación de octubre fue "&ROUND(Nomina_Mensual!H7*100,1)&"% ("&Nomina_Mensual!G7&IF(Nomina_Mensual!G7=1," baja"," bajas")&"), "&IF(Nomina_Mensual!H7>Nomina_Mensual!H6,"mayor","menor o igual")&" que la de septiembre ("&ROUND(Nomina_Mensual!H6*100,1)&"%)." -> • La rotación de octubre fue 3.3% (4 bajas), mayor que la de septiembre (1.7%).
R51: ="• El desempeño explica cerca del "&ROUND(Calculos!B31*100,0)&"% de la variación salarial (R² = "&ROUND(Calculos!B31,2)&")." -> • El desempeño explica cerca del 71% de la variación salarial (R² = 0.71).
R55: ="• El "&ROUND(Nomina_Mensual!I7*100,1)&"% de los pagos de octubre llegó a tiempo ("&IF(Nomina_Mensual!I7>=Nomina_Mensual!I6,"igual o mejor","peor")&" que en septiembre: "&ROUND(Nomina_Mensual!I6*100,1)&"%)." -> • El 99.2% de los pagos de octubre llegó a tiempo (igual o mejor que en septiembre: 98.3%).
J58: ="R² = "&ROUND(Calculos!B31,2)&" · a mayor rating de desempeño, mayor salario (todos los vigentes)" -> R² = 0.71 · a mayor rating de desempeño, mayor salario (todos los vigentes)
B61: Cómo leer este panel
B62: • Selector amarillo (arriba): filtra tarjetas, tendencia, histograma y hallazgos por departamento. Los gráficos de salario y de dotación por departamento siempre comparan los 5 departamentos, y la dispersión muestra a todos los vigentes. • Todo se calcula con fórmulas desde las hojas Datos y Pagos (ver detalle en Formulas_Clave). Los datos son 100% ficticios. • Empleados = activos + en licencia. Rotación = bajas del mes / headcount a fin de mes. Variaciones de % se muestran en puntos porcentuales (pp). En rotación, una subida se marca en rojo.

Sheet Datos
A1: ID Empleado | B1: Nombre | C1: Departamento | D1: Puesto | E1: Nivel | F1: Salario Mensual | G1: Fecha Ingreso | H1: Estado | I1: Rating Desempeño | J1: Fecha Baja
A2: E001 | B2: Lucía Rodríguez | C2: Ventas | D2: Ejecutivo de Ventas | E2: Analista | F2: 3760 | G2: 44609 | H2: Activo | I2: 4.5
A3: E003 | B3: Julieta Fernández | C3: Operaciones | D3: Especialista en Soporte | E3: Especialista | F3: 3010 | G3: 44687 | H3: Activo | I3: 3.5
A4: E004 | B4: Isabella Suárez | C4: IT | D4: Arquitecto de Software | E4: Senior | F4: 3270 | G4: 44768 | H4: Licencia | I4: 2.9
A5: E006 | B5: Ramiro López | C5: Ventas | D5: Account Manager | E5: Senior | F5: 3550 | G5: 44886 | H5: Activo | I5: 3.8
A6: E007 | B6: Valentina Ramírez | C6: IT | D6: QA Analyst | E6: Analista | F6: 3130 | G6: 44907 | H6: Activo | I6: 3
A7: E008 | B7: Leandro Ibáñez | C7: IT | D7: Desarrollador Sr | E7: Senior | F7: 4100 | G7: 44910 | H7: Activo | I7: 4
A8: E009 | B8: Antonia Acosta | C8: IT | D8: Desarrollador Sr | E8: Senior | F8: 4840 | G8: 44968 | H8: Activo | I8: 4.8
A9: E011 | B9: Bruno Acosta | C9: IT | D9: Arquitecto de Software | E9: Senior | F9: 3760 | G9: 44971 | H9: Activo | I9: 3.5
A10: E012 | B10: Daniela Núñez | C10: Operaciones | D10: Especialista en Soporte | E10: Especialista | F10: 2720 | G10: 44974 | H10: Activo | I10: 3.3
A11: E013 | B11: Emiliano Vera | C11: IT | D11: Arquitecto de Software | E11: Senior | F11: 3390 | G11: 44984 | H11: Activo | I11: 3.1
A12: E014 | B12: Catalina Pérez | C12: IT | D12: Desarrollador Jr | E12: Junior | F12: 3480 | G12: 44994 | H12: Activo | I12: 3.8
A13: E015 | B13: Camila Ramírez | C13: RRHH | D13: Generalista de RRHH | E13: Analista | F13: 2990 | G13: 45032 | H13: Activo | I13: 3.2
... A121: E132 | B121: Antonella Ibáñez | C121: IT | D121: Arquitecto de Software | E121: Senior | F121: 3510 | G121: 46302 | H121: Activo | I121: 3.3
A122: E002 | B122: Ramiro Romero | C122: IT | D122: Desarrollador Jr | E122: Junior | F122: 3390 | G122: 44627 | H122: Baja | I122: 3.6 | J122: 46288
A123: E005 | B123: Joaquín Núñez | C123: Ventas | D123: Account Manager | E123: Senior | F123: 3900 | G123: 44881 | H123: Baja | I123: 4.4 | J123: 46153
A124: E010 | B124: Joaquín Medina | C124: RRHH | D124: Generalista de RRHH | E124: Analista | F124: 2570 | G124: 44971 | H124: Baja | I124: 2.6 | J124: 46308
A125: E016 | B125: Ramiro Núñez | C125: Operaciones | D125: Analista de Operaciones | E125: Analista | F125: 2450 | G125: 45033 | H125: Baja | I125: 2.6 | J125: 46197
A126: E031 | B126: Matías Gómez | C126: IT | D126: Arquitecto de Software | E126: Senior | F126: 3600 | G126: 45232 | H126: Baja | I126: 3.3 | J126: 46274
A127: E039 | B127: Valeria Silva | C127: Ventas | D127: Ejecutivo de Ventas | E127: Analista | F127: 2250 | G127: 45297 | H127: Baja | I127: 2.5 | J127: 46310
A128: E054 | B128: Emilia García | C128: IT | D128: Arquitecto de Software | E128: Senior | F128: 3370 | G128: 45485 | H128: Baja | I128: 3.2 | J128: 46243
A129: E056 | B129: Catalina Romero | C129: RRHH | D129: Generalista de RRHH | E129: Analista | F129: 3020 | G129: 45490 | H129: Baja | I129: 3.2 | J129: 46248
A130: E078 | B130: Catalina Ramírez | C130: Ventas | D130: Representante Comercial | E130: Junior | F130: 3240 | G130: 45758 | H130: Baja | I130: 4.3 | J130: 46221
A131: E090 | B131: Lucía Rivas | C131: Operaciones | D131: Especialista en Soporte | E131: Especialista | F131: 2100 | G131: 45997 | H131: Baja | I131: 2.1 | J131: 46315
A132: E099 | B132: Emilia Herrera | C132: Ventas | D132: Representante Comercial | E132: Junior | F132: 2200 | G132: 46087 | H132: Baja | I132: 2.6 | J132: 46181
A133: E102 | B133: Valeria Ramírez | C133: Ventas | D133: Representante Comercial | E133: Junior | F133: 3180 | G133: 46109 | H133: Baja | I133: 3.9 | J133: 46310
A135: Nota: datos 100% ficticios, generados para fines de portafolio. Las filas de Estado = 'Baja' (ex-empleados con Fecha Baja) van al final de la tabla. 'Licencia' cuenta como empleado vigente.

Sheet Pagos
A1: ID Empleado | B1: Departamento | C1: Mayo 2026 | D1: Junio 2026 | E1: Julio 2026 | F1: Agosto 2026 | G1: Septiembre 2026 | H1: Octubre 2026
A2: E001 | B2: =INDEX(Datos_Departamento,MATCH(A2,Datos_ID,0)) -> Ventas | C2: Sí | D2: Sí | E2: No | F2: Sí | G2: Sí | H2: Sí
A3: E003 | B3: =INDEX(Datos_Departamento,MATCH(A3,Datos_ID,0)) -> Operaciones | C3: Sí | D3: Sí | E3: Sí | F3: Sí | G3: Sí | H3: Sí
A4: E004 | B4: =INDEX(Datos_Departamento,MATCH(A4,Datos_ID,0)) -> IT | C4: No | D4: Sí | E4: Sí | F4: Sí | G4: Sí | H4: Sí
A5: E006 | B5: =INDEX(Datos_Departamento,MATCH(A5,Datos_ID,0)) -> Ventas | C5: Sí | D5: Sí | E5: Sí | F5: Sí | G5: Sí | H5: No
A6: E007 | B6: =INDEX(Datos_Departamento,MATCH(A6,Datos_ID,0)) -> IT | C6: Sí | D6: Sí | E6: Sí | F6: Sí | G6: Sí | H6: Sí
A7: E008 | B7: =INDEX(Datos_Departamento,MATCH(A7,Datos_ID,0)) -> IT | C7: Sí | D7: Sí | E7: Sí | F7: Sí | G7: Sí | H7: Sí
A8: E009 | B8: =INDEX(Datos_Departamento,MATCH(A8,Datos_ID,0)) -> IT | C8: Sí | D8: Sí | E8: Sí | F8: Sí | G8: Sí | H8: Sí
A9: E011 | B9: =INDEX(Datos_Departamento,MATCH(A9,Datos_ID,0)) -> IT | C9: Sí | D9: Sí | E9: Sí | F9: Sí | G9: Sí | H9: Sí
A10: E012 | B10: =INDEX(Datos_Departamento,MATCH(A10,Datos_ID,0)) -> Operaciones | C10: Sí | D10: Sí | E10: Sí | F10: Sí | G10: Sí | H10: Sí
A11: E013 | B11: =INDEX(Datos_Departamento,MATCH(A11,Datos_ID,0)) -> IT | C11: Sí | D11: Sí | E11: Sí | F11: Sí | G11: Sí | H11: Sí
A12: E014 | B12: =INDEX(Datos_Departamento,MATCH(A12,Datos_ID,0)) -> IT | C12: Sí | D12: Sí | E12: Sí | F12: Sí | G12: Sí | H12: Sí
A13: E015 | B13: =INDEX(Datos_Departamento,MATCH(A13,Datos_ID,0)) -> RRHH | C13: Sí | D13: Sí | E13: Sí | F13: Sí | G13: Sí | H13: Sí
... A97: E108 | B97: =INDEX(Datos_Departamento,MATCH(A97,Datos_ID,0)) -> Operaciones | C97: Sí | D97: Sí | E97: Sí | F97: Sí | G97: Sí | H97: Sí
A98: E109 | B98: =INDEX(Datos_Departamento,MATCH(A98,Datos_ID,0)) -> Ventas | D98: Sí | E98: Sí | F98: Sí | G98: Sí | H98: Sí
A99: E110 | B99: =INDEX(Datos_Departamento,MATCH(A99,Datos_ID,0)) -> IT | D99: Sí | E99: Sí | F99: Sí | G99: Sí | H99: Sí
A100: E111 | B100: =INDEX(Datos_Departamento,MATCH(A100,Datos_ID,0)) -> RRHH | D100: Sí | E100: Sí | F100: Sí | G100: Sí | H100: Sí
A101: E112 | B101: =INDEX(Datos_Departamento,MATCH(A101,Datos_ID,0)) -> RRHH | D101: Sí | E101: Sí | F101: Sí | G101: Sí | H101: Sí
A102: E113 | B102: =INDEX(Datos_Departamento,MATCH(A102,Datos_ID,0)) -> Ventas | D102: Sí | E102: Sí | F102: Sí | G102: Sí | H102: Sí
A103: E114 | B103: =INDEX(Datos_Departamento,MATCH(A103,Datos_ID,0)) -> Operaciones | E103: Sí | F103: Sí | G103: Sí | H103: Sí
A104: E115 | B104: =INDEX(Datos_Departamento,MATCH(A104,Datos_ID,0)) -> Operaciones | E104: Sí | F104: Sí | G104: Sí | H104: Sí
A105: E116 | B105: =INDEX(Datos_Departamento,MATCH(A105,Datos_ID,0)) -> Ventas | E105: Sí | F105: Sí | G105: Sí | H105: Sí
A106: E117 | B106: =INDEX(Datos_Departamento,MATCH(A106,Datos_ID,0)) -> Ventas | E106: Sí | F106: Sí | G106: No | H106: Sí
A107: E118 | B107: =INDEX(Datos_Departamento,MATCH(A107,Datos_ID,0)) -> Operaciones | F107: Sí | G107: Sí | H107: Sí
A108: E119 | B108: =INDEX(Datos_Departamento,MATCH(A108,Datos_ID,0)) -> RRHH | F108: Sí | G108: Sí | H108: Sí
A109: E120 | B109: =INDEX(Datos_Departamento,MATCH(A109,Datos_ID,0)) -> Finanzas | F109: Sí | G109: Sí | H109: Sí
A110: E121 | B110: =INDEX(Datos_Departamento,MATCH(A110,Datos_ID,0)) -> Finanzas | F110: Sí | G110: Sí | H110: Sí
A111: E122 | B111: =INDEX(Datos_Departamento,MATCH(A111,Datos_ID,0)) -> RRHH | F111: Sí | G111: Sí | H111: Sí
A112: E123 | B112: =INDEX(Datos_Departamento,MATCH(A112,Datos_ID,0)) -> IT | G112: Sí | H112: Sí
A113: E124 | B113: =INDEX(Datos_Departamento,MATCH(A113,Datos_ID,0)) -> Ventas | G113: Sí | H113: Sí
A114: E125 | B114: =INDEX(Datos_Departamento,MATCH(A114,Datos_ID,0)) -> IT | G114: Sí | H114: Sí
A115: E126 | B115: =INDEX(Datos_Departamento,MATCH(A115,Datos_ID,0)) -> RRHH | G115: Sí | H115: Sí
A116: E127 | B116: =INDEX(Datos_Departamento,MATCH(A116,Datos_ID,0)) -> Finanzas | H116: Sí
A117: E128 | B117: =INDEX(Datos_Departamento,MATCH(A117,Datos_ID,0)) -> IT | H117: Sí
A118: E129 | B118: =INDEX(Datos_Departamento,MATCH(A118,Datos_ID,0)) -> Operaciones | H118: Sí
A119: E130 | B119: =INDEX(Datos_Departamento,MATCH(A119,Datos_ID,0)) -> RRHH | H119: Sí
A120: E131 | B120: =INDEX(Datos_Departamento,MATCH(A120,Datos_ID,0)) -> IT | H120: Sí
A121: E132 | B121: =INDEX(Datos_Departamento,MATCH(A121,Datos_ID,0)) -> IT | H121: Sí
A122: E002 | B122: =INDEX(Datos_Departamento,MATCH(A122,Datos_ID,0)) -> IT | C122: Sí | D122: Sí | E122: Sí | F122: Sí | G122: Sí
A123: E005 | B123: =INDEX(Datos_Departamento,MATCH(A123,Datos_ID,0)) -> Ventas | C123: Sí
...

Sheet Nomina_Mensual
A1: Mes | B1: Inicio de mes | C1: Fin de mes | D1: Headcount | E1: Costo Nómina ($) | F1: Contrataciones | G1: Bajas | H1: Rotación % | I1: % Pago a Tiempo | J1: Salario Promedio ($)
A2: Mayo | B2: 46143 | C2: 46173 | D2: =COUNTIFS(Datos_Departamento,Crit_Depto,Datos_Ingreso,"<="&C2)-COUNTIFS(Datos_Departamento,Crit_Depto,Datos_Baja,"<="&C2) -> 107 | E2: =SUMIFS(Datos_Salario,Datos_Departamento,Crit_Depto,Datos_Ingreso,"<="&C2)-SUMIFS(Datos_Salario,Datos_Departamento,Crit_Depto,Datos_Baja,"<="&C2) -> 354390 | F2: =COUNTIFS(Datos_Departamento,Crit_Depto,Datos_Ingreso,">="&B2,Datos_Ingreso,"<="&C2) -> 4 | G2: =COUNTIFS(Datos_Departamento,Crit_Depto,Datos_Baja,">="&B2,Datos_Baja,"<="&C2) -> 1 | H2: =IFERROR(G2/D2,0) -> 0.0093457944 | I2: =IFERROR(COUNTIFS(Pagos!$B$2:$B$133,Crit_Depto,Pagos!C$2:C$133,"Sí")/(COUNTIFS(Pagos!$B$2:$B$133,Crit_Depto,Pagos!C$2:C$133,"Sí")+COUNTIFS(Pagos!$B$2:$B$133,Crit_Depto,Pagos!C$2:C$133,"No")),0) -> 0.96296296 | J2: =IFERROR(E2/D2,0) -> 3312.0561
A3: Junio | B3: 46174 | C3: 46203 | D3: =COUNTIFS(Datos_Departamento,Crit_Depto,Datos_Ingreso,"<="&C3)-COUNTIFS(Datos_Departamento,Crit_Depto,Datos_Baja,"<="&C3) -> 110 | E3: =SUMIFS(Datos_Salario,Datos_Departamento,Crit_Depto,Datos_Ingreso,"<="&C3)-SUMIFS(Datos_Salario,Datos_Departamento,Crit_Depto,Datos_Baja,"<="&C3) -> 366120 | F3: =COUNTIFS(Datos_Departamento,Crit_Depto,Datos_Ingreso,">="&B3,Datos_Ingreso,"<="&C3) -> 5 | G3: =COUNTIFS(Datos_Departamento,Crit_Depto,Datos_Baja,">="&B3,Datos_Baja,"<="&C3) -> 2 | H3: =IFERROR(G3/D3,0) -> 0.018181818 | I3: =IFERROR(COUNTIFS(Pagos!$B$2:$B$133,Crit_Depto,Pagos!D$2:D$133,"Sí")/(COUNTIFS(Pagos!$B$2:$B$133,Crit_Depto,Pagos!D$2:D$133,"Sí")+COUNTIFS(Pagos!$B$2:$B$133,Crit_Depto,Pagos!D$2:D$133,"No")),0) -> 0.97321429 | J3: =IFERROR(E3/D3,0) -> 3328.3636
A4: Julio | B4: 46204 | C4: 46234 | D4: =COUNTIFS(Datos_Departamento,Crit_Depto,Datos_Ingreso,"<="&C4)-COUNTIFS(Datos_Departamento,Crit_Depto,Datos_Baja,"<="&C4) -> 113 | E4: =SUMIFS(Datos_Salario,Datos_Departamento,Crit_Depto,Datos_Ingreso,"<="&C4)-SUMIFS(Datos_Salario,Datos_Departamento,Crit_Depto,Datos_Baja,"<="&C4) -> 375830 | F4: =COUNTIFS(Datos_Departamento,Crit_Depto,Datos_Ingreso,">="&B4,Datos_Ingreso,"<="&C4) -> 4 | G4: =COUNTIFS(Datos_Departamento,Crit_Depto,Datos_Baja,">="&B4,Datos_Baja,"<="&C4) -> 1 | H4: =IFERROR(G4/D4,0) -> 0.0088495575 | I4: =IFERROR(COUNTIFS(Pagos!$B$2:$B$133,Crit_Depto,Pagos!E$2:E$133,"Sí")/(COUNTIFS(Pagos!$B$2:$B$133,Crit_Depto,Pagos!E$2:E$133,"Sí")+COUNTIFS(Pagos!$B$2:$B$133,Crit_Depto,Pagos!E$2:E$133,"No")),0) -> 0.97368421 | J4: =IFERROR(E4/D4,0) -> 3325.9292
A5: Agosto | B5: 46235 | C5: 46265 | D5: =COUNTIFS(Datos_Departamento,Crit_Depto,Datos_Ingreso,"<="&C5)-COUNTIFS(Datos_Departamento,Crit_Depto,Datos_Baja,"<="&C5) -> 116 | E5: =SUMIFS(Datos_Salario,Datos_Departamento,Crit_Depto,Datos_Ingreso,"<="&C5)-SUMIFS(Datos_Salario,Datos_Departamento,Crit_Depto,Datos_Baja,"<="&C5) -> 386050 | F5: =COUNTIFS(Datos_Departamento,Crit_Depto,Datos_Ingreso,">="&B5,Datos_Ingreso,"<="&C5) -> 5 | G5: =COUNTIFS(Datos_Departamento,Crit_Depto,Datos_Baja,">="&B5,Datos_Baja,"<="&C5) -> 2 | H5: =IFERROR(G5/D5,0) -> 0.017241379 | I5: =IFERROR(COUNTIFS(Pagos!$B$2:$B$133,Crit_Depto,Pagos!F$2:F$133,"Sí")/(COUNTIFS(Pagos!$B$2:$B$133,Crit_Depto,Pagos!F$2:F$133,"Sí")+COUNTIFS(Pagos!$B$2:$B$133,Crit_Depto,Pagos!F$2:F$133,"No")),0) -> 0.98305085 | J5: =IFERROR(E5/D5,0) -> 3328.0172
A6: Septiembre | B6: 46266 | C6: 46295 | D6: =COUNTIFS(Datos_Departamento,Crit_Depto,Datos_Ingreso,"<="&C6)-COUNTIFS(Datos_Departamento,Crit_Depto,Datos_Baja,"<="&C6) -> 118 | E6: =SUMIFS(Datos_Salario,Datos_Departamento,Crit_Depto,Datos_Ingreso,"<="&C6)-SUMIFS(Datos_Salario,Datos_Departamento,Crit_Depto,Datos_Baja,"<="&C6) -> 393260 | F6: =COUNTIFS(Datos_Departamento,Crit_Depto,Datos_Ingreso,">="&B6,Datos_Ingreso,"<="&C6) -> 4 | G6: =COUNTIFS(Datos_Departamento,Crit_Depto,Datos_Baja,">="&B6,Datos_Baja,"<="&C6) -> 2 | H6: =IFERROR(G6/D6,0) -> 0.016949153 | I6: =IFERROR(COUNTIFS(Pagos!$B$2:$B$133,Crit_Depto,Pagos!G$2:G$133,"Sí")/(COUNTIFS(Pagos!$B$2:$B$133,Crit_Depto,Pagos!G$2:G$133,"Sí")+COUNTIFS(Pagos!$B$2:$B$133,Crit_Depto,Pagos!G$2:G$133,"No")),0) -> 0.98333333 | J6: =IFERROR(E6/D6,0) -> 3332.7119
A7: Octubre | B7: 46296 | C7: 46326 | D7: =COUNTIFS(Datos_Departamento,Crit_Depto,Datos_Ingreso,"<="&C7)-COUNTIFS(Datos_Departamento,Crit_Depto,Datos_Baja,"<="&C7) -> 120 | E7: =SUMIFS(Datos_Salario,Datos_Departamento,Crit_Depto,Datos_Ingreso,"<="&C7)-SUMIFS(Datos_Salario,Datos_Departamento,Crit_Depto,Datos_Baja,"<="&C7) -> 404470 | F7: =COUNTIFS(Datos_Departamento,Crit_Depto,Datos_Ingreso,">="&B7,Datos_Ingreso,"<="&C7) -> 6 | G7: =COUNTIFS(Datos_Departamento,Crit_Depto,Datos_Baja,">="&B7,Datos_Baja,"<="&C7) -> 4 | H7: =IFERROR(G7/D7,0) -> 0.033333333 | I7: =IFERROR(COUNTIFS(Pagos!$B$2:$B$133,Crit_Depto,Pagos!H$2:H$133,"Sí")/(COUNTIFS(Pagos!$B$2:$B$133,Crit_Depto,Pagos!H$2:H$133,"Sí")+COUNTIFS(Pagos!$B$2:$B$133,Crit_Depto,Pagos!H$2:H$133,"No")),0) -> 0.99193548 | J7: =IFERROR(E7/D7,0) -> 3370.5833
A9: Todo se calcula desde las hojas Datos y Pagos y responde al selector de departamento del Dashboard. Headcount = ingresados a fin de mes menos bajas a fin de mes. Octubre incluye datos hasta el 20/10/2026.

Sheet Calculos
A1: Cálculos de KPI (alimentan el Dashboard)
A2: Departamento seleccionado | B2: =Dashboard!$E$6 -> Todos
A3: Criterio usado en las fórmulas | B3: =IF(B2="Todos","*",B2) -> *
A5: Indicador | B5: Valor Actual (Oct) | C5: Mes Anterior (Sep) | D5: Variación
A6: Total Empleados | B6: =Nomina_Mensual!D7 -> 120 | C6: =Nomina_Mensual!D6 -> 118 | D6: =IFERROR((B6-C6)/C6,0) -> 0.016949153
A7: Costo Total de Nómina | B7: =Nomina_Mensual!E7 -> 404470 | C7: =Nomina_Mensual!E6 -> 393260 | D7: =IFERROR((B7-C7)/C7,0) -> 0.028505315
A8: Salario Promedio | B8: =Nomina_Mensual!J7 -> 3370.5833 | C8: =Nomina_Mensual!J6 -> 3332.7119 | D8: =IFERROR((B8-C8)/C8,0) -> 0.011363559
A9: % Pago a Tiempo | B9: =Nomina_Mensual!I7 -> 0.99193548 | C9: =Nomina_Mensual!I6 -> 0.98333333 | D9: =B9-C9 -> 0.0086021505
A10: Nuevas Contrataciones | B10: =Nomina_Mensual!F7 -> 6 | C10: =Nomina_Mensual!F6 -> 4 | D10: =IFERROR((B10-C10)/C10,0) -> 0.5
A11: Tasa de Rotación | B11: =Nomina_Mensual!H7 -> 0.033333333 | C11: =Nomina_Mensual!H6 -> 0.016949153 | D11: =B11-C11 -> 0.016384181
A14: Departamento | B14: Salario Promedio | C14: Headcount
A15: IT | B15: =IFERROR(AVERAGEIFS(Datos_Salario,Datos_Departamento,A15,Datos_Estado,"<>Baja"),0) -> 3803.2432 | C15: =COUNTIFS(Datos_Departamento,A15,Datos_Estado,"<>Baja") -> 37
A16: RRHH | B16: =IFERROR(AVERAGEIFS(Datos_Salario,Datos_Departamento,A16,Datos_Estado,"<>Baja"),0) -> 3193.7931 | C16: =COUNTIFS(Datos_Departamento,A16,Datos_Estado,"<>Baja") -> 29
A17: Finanzas | B17: =IFERROR(AVERAGEIFS(Datos_Salario,Datos_Departamento,A17,Datos_Estado,"<>Baja"),0) -> 3517.3333 | C17: =COUNTIFS(Datos_Departamento,A17,Datos_Estado,"<>Baja") -> 15
A18: Ventas | B18: =IFERROR(AVERAGEIFS(Datos_Salario,Datos_Departamento,A18,Datos_Estado,"<>Baja"),0) -> 3043.1579 | C18: =COUNTIFS(Datos_Departamento,A18,Datos_Estado,"<>Baja") -> 19
A19: Operaciones | B19: =IFERROR(AVERAGEIFS(Datos_Salario,Datos_Departamento,A19,Datos_Estado,"<>Baja"),0) -> 3027.5 | C19: =COUNTIFS(Datos_Departamento,A19,Datos_Estado,"<>Baja") -> 20
A22: Rango Salarial | B22: Empleados vigentes
A23: < $2.5K | B23: =COUNTIFS(Datos_Departamento,Crit_Depto,Datos_Estado,"<>Baja",Datos_Salario,"<2500") -> 7
A24: $2.5K - $3.0K | B24: =COUNTIFS(Datos_Departamento,Crit_Depto,Datos_Estado,"<>Baja",Datos_Salario,">=2500",Datos_Salario,"<3000") -> 25
A25: $3.0K - $3.5K | B25: =COUNTIFS(Datos_Departamento,Crit_Depto,Datos_Estado,"<>Baja",Datos_Salario,">=3000",Datos_Salario,"<3500") -> 40
A26: $3.5K - $4.0K | B26: =COUNTIFS(Datos_Departamento,Crit_Depto,Datos_Estado,"<>Baja",Datos_Salario,">=3500",Datos_Salario,"<4000") -> 30
A27: $4.0K - $4.5K | B27: =COUNTIFS(Datos_Departamento,Crit_Depto,Datos_Estado,"<>Baja",Datos_Salario,">=4000",Datos_Salario,"<4500") -> 12
A28: > $4.5K | B28: =COUNTIFS(Datos_Departamento,Crit_Depto,Datos_Estado,"<>Baja",Datos_Salario,">=4500") -> 6
A31: R² desempeño vs. salario (vigentes) | B31: =RSQ(Vig_Salario,Vig_Rating) -> 0.70675011

Sheet Formulas_Clave
A1: Fórmulas clave de los KPI
A3: KPI | B3: Fórmula Excel (ejemplo, fila de octubre) | C3: Explicación
A4: Criterio de departamento | B4: =IF(Dashboard!E6="Todos","*",Dashboard!E6) | C4: Si el selector dice 'Todos' usa el comodín * (cualquier texto); si no, filtra por ese departamento. Se reutiliza como Crit_Depto.
A5: Total Empleados (Headcount) | B5: =COUNTIFS(Datos_Departamento,Crit_Depto,Datos_Ingreso,"<="&C7)-COUNTIFS(Datos_Departamento,Crit_Depto,Datos_Baja,"<="&C7) | C5: Ingresados a fin de mes menos los que ya tienen fecha de baja. Incluye personal en licencia.
A6: Costo Total de Nómina | B6: =SUMIFS(Datos_Salario,Datos_Departamento,Crit_Depto,Datos_Ingreso,"<="&C7)-SUMIFS(Datos_Salario,Datos_Departamento,Crit_Depto,Datos_Baja,"<="&C7) | C6: Suma de salarios de los vigentes a fin de mes.
A7: Salario Promedio | B7: =IFERROR(E7/D7,0) | C7: Costo de nómina dividido por el headcount del mes.
A8: % Pago a Tiempo | B8: =COUNTIFS(Pagos!B:B,Crit_Depto,Pagos!H:H,"Sí")/(COUNTIFS(...,"Sí")+COUNTIFS(...,"No")) | C8: Pagos hechos a tiempo sobre el total de pagos del mes (hoja Pagos).
A9: Nuevas Contrataciones | B9: =COUNTIFS(Datos_Departamento,Crit_Depto,Datos_Ingreso,">="&B7,Datos_Ingreso,"<="&C7) | C9: Empleados cuya fecha de ingreso cae dentro del mes.
A10: Tasa de Rotación | B10: =IFERROR(G7/D7,0) | C10: Bajas del mes (fecha de baja dentro del mes) dividido por el headcount a fin de mes.
A11: Variación vs. mes anterior | B11: =IFERROR((B6-C6)/C6,0) | =B9-C9 (en pp para porcentajes) | C11: Variación relativa para cantidades y montos; diferencia en puntos porcentuales para % de pago y rotación.
A12: Salario Promedio por Depto. | B12: =AVERAGEIFS(Datos_Salario,Datos_Departamento,"IT",Datos_Estado,"<>Baja") | C12: Promedio de vigentes por departamento (hoja Calculos).
A13: Distribución salarial | B13: =COUNTIFS(Datos_Departamento,Crit_Depto,Datos_Estado,"<>Baja",Datos_Salario,">=2500",Datos_Salario,"<3000") | C13: Cuenta vigentes por rango de salario; alimenta el histograma.
A14: R² desempeño vs. salario | B14: =RSQ(Vig_Salario,Vig_Rating) | C14: Qué parte de la variación salarial explica el rating de desempeño.
